Warning: Could not import some modules: No module named 'src'
PYTHONPATH head: ['/Users/remyroche/Documents/Ares/src', '/Users/remyroche/Documents/Ares/src/training/steps', '/Library/Frameworks/Python.framework/Versions/3.11/lib/python311.zip', '/Library/Frameworks/Python.framework/Versions/3.11/lib/python3.11', '/Library/Frameworks/Python.framework/Versions/3.11/lib/python3.11/lib-dynload']
Project root injected: /Users/remyroche/Documents/Ares/src
================================================================================
ðŸš€ STEP1 SCRIPT STARTING
================================================================================
Arguments: ['src/training/steps/step1_data_collection.py', 'ETHUSDT', 'BINANCE', '1000', 'data_cache', '730']
Current working directory: /Users/remyroche/Documents/Ares
Python path: ['/Users/remyroche/Documents/Ares/src', '/Users/remyroche/Documents/Ares/src/training/steps', '/Library/Frameworks/Python.framework/Versions/3.11/lib/python311.zip']...
Starting import handling...
Parsed lookback_days: 730
Parsed arguments:
  Symbol: ETHUSDT
  Exchange: BINANCE
  Min data points: 1000
  Data dir: data_cache
  Lookback days: 730
Starting asyncio.run...
INFO:Step1Fallback.Step1DataCollection:================================================================================
INFO:Step1Fallback.Step1DataCollection:ðŸš€ STEP 1: DATA COLLECTION START
INFO:Step1Fallback.Step1DataCollection:================================================================================
INFO:Step1Fallback.Step1DataCollection:Start time: 2025-08-10 00:40:37
INFO:Step1Fallback.Step1DataCollection:Symbol: ETHUSDT
INFO:Step1Fallback.Step1DataCollection:Exchange: BINANCE
INFO:Step1Fallback.Step1DataCollection:Min data points: 1000
INFO:Step1Fallback.Step1DataCollection:Data directory: data_cache
INFO:Step1Fallback.Step1DataCollection:Lookback days: 730
INFO:Step1Fallback.Step1DataCollection:Python version: 3.11.1 (v3.11.1:a7a450f84a, Dec  6 2022, 15:24:06) [Clang 13.0.0 (clang-1300.0.29.30)]
INFO:Step1Fallback.Step1DataCollection:Working directory: /Users/remyroche/Documents/Ares
================================================================================
ðŸš€ STEP 1: DATA COLLECTION START
================================================================================
INFO:Step1Fallback.Step1DataCollection:ðŸ“¥ STEP 1.1: Data download...
INFO:Step1Fallback.Step1DataCollection:   Starting data download...
   Starting data download...
WARNING:Step1Fallback.Step1Fallback.DataDownloaderAdapter:Fallback unable to import real downloader; returning False: No module named 'src'
WARNING:Step1Fallback.Step1Fallback.DataDownloaderAdapter:sys.path[0:5]=['/Users/remyroche/Documents/Ares/src', '/Users/remyroche/Documents/Ares/src/training/steps', '/Library/Frameworks/Python.framework/Versions/3.11/lib/python311.zip', '/Library/Frameworks/Python.framework/Versions/3.11/lib/python3.11', '/Library/Frameworks/Python.framework/Versions/3.11/lib/python3.11/lib-dynload']
WARNING:Step1Fallback.Step1Fallback.DataDownloaderAdapter:project_root=/Users/remyroche/Documents/Ares/src
INFO:Step1Fallback.Step1DataCollection:   download_all_data_with_consolidation completed: False
   download_all_data_with_consolidation completed: False
ERROR: ðŸ’¥ Unexpected error in data collection: {e}
ERROR: Full traceback:
ERROR:Step1Fallback.Step1DataCollection:Traceback (most recent call last):
  File "/Users/remyroche/Documents/Ares/src/training/steps/step1_data_collection.py", line 1913, in run_step
    raise RuntimeError(
RuntimeError: Data download step failed. Check downloader logs for details.
Traceback (most recent call last):
  File "/Users/remyroche/Documents/Ares/src/training/steps/step1_data_collection.py", line 1913, in run_step
    raise RuntimeError(
RuntimeError: Data download step failed. Check downloader logs for details.
asyncio.run completed. Results:
  klines_df: <class 'NoneType'> with None rows
  agg_trades_df: <class 'NoneType'> with None rows
  futures_df: <class 'NoneType'> with None rows
FAILED: Step1 failed - klines_df is None
